<?xml version="1.0" encoding="utf-8"?>
<!-- This URDF was automatically created by SolidWorks to URDF Exporter! Originally created by Stephen Brawner (brawner@gmail.com) 
     Commit Version: 1.6.0-4-g7f85cfe  Build Version: 1.6.7995.38578
     For more information, please see http://wiki.ros.org/sw_urdf_exporter -->
<!-- Modified: Removed wrist components, added base_link with origin at wrist center -->
<robot
  name="RH56DFX_R_with_Wrist">
  <!-- Base link at wrist center -->
  <link name="base_link">
    <inertial>
      <origin xyz="0 0 0" rpy="0 0 0"/>
      <mass value="0.001"/>
      <inertia ixx="1e-9" ixy="0" ixz="0" iyy="1e-9" iyz="0" izz="1e-9"/>
    </inertial>
  </link>
  <link
    name="r_hand_base">
    <inertial>
      <origin
        xyz="0.00186722142687372 0.03425462641545 0.014403857640475"
        rpy="0 0 0" />
      <mass
        value="0.460583267266941" />
      <inertia
        ixx="0.000329494407160081"
        ixy="1.91477414348783E-06"
        ixz="-1.39936390260134E-06"
        iyy="0.000194341011884896"
        iyz="1.21251307175976E-06"
        izz="0.000213768215595836" />
    </inertial>
    <visual>
      <origin
        xyz="0 0 0"
        rpy="0 0 0" />
      <geometry>
        <mesh
          filename="package://RH56DFX_R_with_Wrist/meshes/r_hand_base.STL" />
      </geometry>
      <material
        name="">
        <color
          rgba="1 1 1 1" />
      </material>
    </visual>
    <collision>
      <origin
        xyz="0 0 0"
        rpy="0 0 0" />
      <geometry>
        <mesh
          filename="package://RH56DFX_R_with_Wrist/meshes/r_hand_base.STL" />
      </geometry>
    </collision>
  </link>
  <!-- Fixed joint to position hand relative to wrist center -->
  <joint name="base_to_hand" type="fixed">
    <origin xyz="-0.00186722142687372 -0.03425462641545 -0.014403857640475" rpy="0 0 0"/>
    <parent link="base_link"/>
    <child link="r_hand_base"/>
  </joint>
  <link
    name="right_thumb_1">
    <inertial>
      <origin
        xyz="-0.00595889954696003 0.00749987058946561 0.00590004983970082"
        rpy="0 0 0" />
      <mass
        value="0.0102994609298547" />
      <inertia
        ixx="1.76726447851816E-06"
        ixy="-1.16505680679328E-07"
        ixz="-1.91636014299629E-12"
        iyy="1.19858591700679E-06"
        iyz="-1.36096862252653E-11"
        izz="1.50620078115847E-06" />
    </inertial>
    <visual>
      <origin
        xyz="0 0 0"
        rpy="0 0 0" />
      <geometry>
        <mesh
          filename="package://RH56DFX_R_with_Wrist/meshes/right_thumb_1.STL" />
      </geometry>
      <material
        name="">
        <color
          rgba="0.827450980392157 0.83921568627451 0.827450980392157 1" />
      </material>
    </visual>
    <collision>
      <origin
        xyz="0 0 0"
        rpy="0 0 0" />
      <geometry>
        <mesh
          filename="package://RH56DFX_R_with_Wrist/meshes/right_thumb_1.STL" />
      </geometry>
    </collision>
  </link>
  <joint
    name="right_thumb_1_joint"
    type="revolute">
    <origin
      xyz="-0.0153000040088447 0.0343000000007003 0.036400000219911"
      rpy="1.5707963267949 0 -3.14159265358979" />
    <parent
      link="r_hand_base" />
    <child
      link="right_thumb_1" />
    <axis
      xyz="0 0 -1" />
    <limit
      lower="0"
      upper="1.310384"
      effort="1"
      velocity="2" />
  </joint>
  <link
    name="right_thumb_2">
    <inertial>
      <origin
        xyz="-0.021702059702569 0.0140073366357873 0.00802385604823092"
        rpy="0 0 0" />
      <mass
        value="0.0314640303708102" />
      <inertia
        ixx="4.77080502997218E-06"
        ixy="2.24565380204443E-06"
        ixz="-1.93384804492673E-09"
        iyy="5.25070317061785E-06"
        iyz="-6.93473068910724E-10"
        izz="9.41384151324246E-06" />
    </inertial>
    <visual>
      <origin
        xyz="0 0 0"
        rpy="0 0 0" />
      <geometry>
        <mesh
          filename="package://RH56DFX_R_with_Wrist/meshes/right_thumb_2.STL" />
      </geometry>
      <material
        name="">
        <color
          rgba="0.890196078431372 0.890196078431372 0.913725490196078 1" />
      </material>
    </visual>
    <collision>
      <origin
        xyz="0 0 0"
        rpy="0 0 0" />
      <geometry>
        <mesh
          filename="package://RH56DFX_R_with_Wrist/meshes/right_thumb_2.STL" />
      </geometry>
    </collision>
  </link>
  <joint
    name="right_thumb_2_joint"
    type="revolute">
    <origin
      xyz="0.0107038256289915 0.00903759464150421 -0.00649999999999998"
      rpy="1.5707963267949 0 -1.83259571459404" />
    <parent
      link="right_thumb_1" />
    <child
      link="right_thumb_2" />
    <axis
      xyz="0 0 -1" />
    <limit
      lower="0"
      upper="0.523477"
      effort="1"
      velocity="2" />
  </joint>
  <link
    name="right_thumb_3">
    <inertial>
      <origin
        xyz="-0.00916388835013904 -0.000213690008193602 0.00750028797357696"
        rpy="0 0 0" />
      <mass
        value="0.00637737480666728" />
      <inertia
        ixx="7.06810039556575E-07"
        ixy="1.8064821102149E-07"
        ixz="-7.56321985719409E-12"
        iyy="5.60101216987723E-07"
        iyz="6.09546956255714E-12"
        izz="8.41964957548188E-07" />
    </inertial>
    <visual>
      <origin
        xyz="0 0 0"
        rpy="0 0 0" />
      <geometry>
        <mesh
          filename="package://RH56DFX_R_with_Wrist/meshes/right_thumb_3.STL" />
      </geometry>
      <material
        name="">
        <color
          rgba="0.890196078431372 0.890196078431372 0.913725490196078 1" />
      </material>
    </visual>
    <collision>
      <origin
        xyz="0 0 0"
        rpy="0 0 0" />
      <geometry>
        <mesh
          filename="package://RH56DFX_R_with_Wrist/meshes/right_thumb_3.STL" />
      </geometry>
    </collision>
  </link>
  <joint
    name="right_thumb_3_joint"
    type="revolute">
    <origin
      xyz="-0.0415838804016112 0.0375080548719081 0.00050000000000007"
      rpy="0 0 0" />
    <parent
      link="right_thumb_2" />
    <child
      link="right_thumb_3" />
    <axis
      xyz="0 0 -1" />
    <limit
      lower="0"
      upper="0.606844"
      effort="1"
      velocity="2" />
      <mimic 
        joint="right_thumb_2_joint"
        multiplier="1.1425"
        offset="0" />
  </joint>
  <link
    name="right_thumb_4">
    <inertial>
      <origin
        xyz="-0.00556381960339052 0.00321786469032558 0.00598762142813954"
        rpy="0 0 0" />
      <mass
        value="0.0025004461294059" />
      <inertia
        ixx="7.83011892756105E-08"
        ixy="4.70576750033798E-08"
        ixz="1.10924492038399E-10"
        iyy="7.83149658560793E-08"
        iyz="-2.74907781669826E-10"
        izz="1.30863162691476E-07" />
    </inertial>
    <visual>
      <origin
        xyz="0 0 0"
        rpy="0 0 0" />
      <geometry>
        <mesh
          filename="package://RH56DFX_R_with_Wrist/meshes/right_thumb_4.STL" />
      </geometry>
      <material
        name="">
        <color
          rgba="0.890196078431372 0.890196078431372 0.913725490196078 1" />
      </material>
    </visual>
    <collision>
      <origin
        xyz="0 0 0"
        rpy="0 0 0" />
      <geometry>
        <mesh
          filename="package://RH56DFX_R_with_Wrist/meshes/right_thumb_4.STL" />
      </geometry>
    </collision>
  </link>
  <joint
    name="right_thumb_4_joint"
    type="revolute">
    <origin
      xyz="-0.0183934390204584 0.0132218952161126 0.0015"
      rpy="0 0 0" />
    <parent
      link="right_thumb_3" />
    <child
      link="right_thumb_4" />
    <axis
      xyz="0 0 -1" />
    <limit
      lower="0"
      upper="0.430866"
      effort="1"
      velocity="2" />
      <mimic 
        joint="right_thumb_3_joint"
        multiplier="0.7508"
        offset="0" />
  </joint>
  <link
    name="right_thumb_rubber_3">
    <inertial>
      <origin
        xyz="0.000133677754111619 0.00249789544313434 -0.00737807315210834"
        rpy="0 0 0" />
      <mass
        value="0.00232428277409971" />
      <inertia
        ixx="1.1738940345995E-07"
        ixy="1.3316403109373E-10"
        ixz="5.42230494538002E-12"
        iyy="6.71016287130116E-08"
        iyz="-7.29911404958279E-09"
        izz="1.17101548394252E-07" />
    </inertial>
    <visual>
      <origin
        xyz="0 0 0"
        rpy="0 0 0" />
      <geometry>
        <mesh
          filename="package://RH56DFX_R_with_Wrist/meshes/right_thumb_rubber_3.STL" />
      </geometry>
      <material
        name="">
        <color
          rgba="0.298039215686275 0.298039215686275 0.298039215686275 1" />
      </material>
    </visual>
    <collision>
      <origin
        xyz="0 0 0"
        rpy="0 0 0" />
      <geometry>
        <mesh
          filename="package://RH56DFX_R_with_Wrist/meshes/right_thumb_rubber_3.STL" />
      </geometry>
    </collision>
  </link>
  <joint
    name="right_thumb_rubber_3_joint"
    type="fixed">
    <origin
      xyz="-0.00161799622019063 0.00970901340884195 0.00599999825111233"
      rpy="-3.14145330992041 1.55262780459038 -2.54991785073113" />
    <parent
      link="right_thumb_4" />
    <child
      link="right_thumb_rubber_3" />
    <axis
      xyz="0 0 0" />
  </joint>
  <link
    name="right_thumb_pad">
    <inertial>
      <origin
        xyz="-3.17863613624736E-08 -0.00152836456065816 -0.0014060654960278"
        rpy="0 0 0" />
      <mass
        value="0.000138969107299723" />
      <inertia
        ixx="3.88380090334865E-10"
        ixy="-2.20402729674617E-15"
        ixz="3.72337458984911E-15"
        iyy="2.48185589616352E-10"
        iyz="-1.23321553256561E-11"
        izz="5.07570387988192E-10" />
    </inertial>
    <visual>
      <origin
        xyz="0 0 0"
        rpy="0 0 0" />
      <geometry>
        <mesh
          filename="package://RH56DFX_R_with_Wrist/meshes/right_thumb_pad.STL" />
      </geometry>
      <material
        name="">
        <color
          rgba="0.298039215686275 0.298039215686275 0.298039215686275 1" />
      </material>
    </visual>
    <collision>
      <origin
        xyz="0 0 0"
        rpy="0 0 0" />
      <geometry>
        <mesh
          filename="package://RH56DFX_R_with_Wrist/meshes/right_thumb_pad.STL" />
      </geometry>
    </collision>
  </link>
  <joint
    name="right_thumb_pad_joint"
    type="fixed">
    <origin
      xyz="1.97306155155508E-05 0.00787683873056354 -0.00108764909180575"
      rpy="-0.32308105919377 -0.0181645215163438 1.44824432616579E-05" />
    <parent
      link="right_thumb_rubber_3" />
    <child
      link="right_thumb_pad" />
    <axis
      xyz="0 0 0" />
  </joint>
  <link
    name="right_thumb_tip">
    <inertial>
      <origin
        xyz="-2.47505902372935E-05 0.00144636195662112 -0.00180325741638071"
        rpy="0 0 0" />
      <mass
        value="0.00017110035356973" />
      <inertia
        ixx="5.03295308586156E-10"
        ixy="1.10384598900224E-12"
        ixz="1.06224755236763E-12"
        iyy="3.76514497106408E-10"
        iyz="8.13921166925614E-11"
        izz="5.79466758416002E-10" />
    </inertial>
    <visual>
      <origin
        xyz="0 0 0"
        rpy="0 0 0" />
      <geometry>
        <mesh
          filename="package://RH56DFX_R_with_Wrist/meshes/right_thumb_tip.STL" />
      </geometry>
      <material
        name="">
        <color
          rgba="0.298039215686275 0.298039215686275 0.298039215686275 1" />
      </material>
    </visual>
    <collision>
      <origin
        xyz="0 0 0"
        rpy="0 0 0" />
      <geometry>
        <mesh
          filename="package://RH56DFX_R_with_Wrist/meshes/right_thumb_tip.STL" />
      </geometry>
    </collision>
  </link>
  <joint
    name="right_thumb_tip_joint"
    type="fixed">
    <origin
      xyz="0.000137071096497604 0.0150376112085459 -0.00754156328997224"
      rpy="-1.34664653486349 -0.0211118546108423 0.0134662732683287" />
    <parent
      link="right_thumb_rubber_3" />
    <child
      link="right_thumb_tip" />
    <axis
      xyz="0 0 0" />
  </joint>
  <link
    name="right_thumb_rubber_2">
    <inertial>
      <origin
        xyz="0.000157140889199783 0.00288556596888331 -0.0090540619335797"
        rpy="0 0 0" />
      <mass
        value="0.000712293475130305" />
      <inertia
        ixx="4.20891301155909E-08"
        ixy="-1.40469831307447E-10"
        ixz="1.37381961636702E-10"
        iyy="5.19654488817118E-08"
        iyz="8.47531049325098E-09"
        izz="3.43756130398348E-08" />
    </inertial>
    <visual>
      <origin
        xyz="0 0 0"
        rpy="0 0 0" />
      <geometry>
        <mesh
          filename="package://RH56DFX_R_with_Wrist/meshes/right_thumb_rubber_2.STL" />
      </geometry>
      <material
        name="">
        <color
          rgba="0.298039215686275 0.298039215686275 0.298039215686275 1" />
      </material>
    </visual>
    <collision>
      <origin
        xyz="0 0 0"
        rpy="0 0 0" />
      <geometry>
        <mesh
          filename="package://RH56DFX_R_with_Wrist/meshes/right_thumb_rubber_2.STL" />
      </geometry>
    </collision>
  </link>
  <joint
    name="right_thumb_rubber_2_joint"
    type="fixed">
    <origin
      xyz="-0.00507003292533311 0.0118736037354007 0.00749998784521028"
      rpy="-3.14159264398177 1.55312580635649 -2.09404843013331" />
    <parent
      link="right_thumb_3" />
    <child
      link="right_thumb_rubber_2" />
    <axis
      xyz="0 0 0" />
  </joint>
  <link
    name="right_thumb_rubber_1">
    <inertial>
      <origin
        xyz="5.25123796278198E-05 -0.00265158184532596 -0.00524156527611314"
        rpy="0 0 0" />
      <mass
        value="0.00149071340727244" />
      <inertia
        ixx="1.88775194707542E-07"
        ixy="6.69255450795096E-11"
        ixz="-4.00394969226025E-10"
        iyy="8.68614474046453E-08"
        iyz="-3.72017830861924E-09"
        izz="2.26648080388043E-07" />
    </inertial>
    <visual>
      <origin
        xyz="0 0 0"
        rpy="0 0 0" />
      <geometry>
        <mesh
          filename="package://RH56DFX_R_with_Wrist/meshes/right_thumb_rubber_1.STL" />
      </geometry>
      <material
        name="">
        <color
          rgba="0.298039215686275 0.298039215686275 0.298039215686275 1" />
      </material>
    </visual>
    <collision>
      <origin
        xyz="0 0 0"
        rpy="0 0 0" />
      <geometry>
        <mesh
          filename="package://RH56DFX_R_with_Wrist/meshes/right_thumb_rubber_1.STL" />
      </geometry>
    </collision>
  </link>
  <joint
    name="right_thumb_rubber_1_joint"
    type="fixed">
    <origin
      xyz="-0.013046553810162 0.0313855611442986 0.00799913310995912"
      rpy="-3.13815940276514 1.56040994467676 -2.19148660953744" />
    <parent
      link="right_thumb_2" />
    <child
      link="right_thumb_rubber_1" />
    <axis
      xyz="0 0 0" />
  </joint>
  <link
    name="right_index_1">
    <inertial>
      <origin
        xyz="0.000461509522881681 0.0116512167073588 0.00590005205650022"
        rpy="0 0 0" />
      <mass
        value="0.00881227150510368" />
      <inertia
        ixx="1.40236362118851E-06"
        ixy="-1.11033984168669E-07"
        ixz="-3.45534161535905E-13"
        iyy="4.33624497078915E-07"
        iyz="-8.02588109417283E-12"
        izz="1.46958690770066E-06" />
    </inertial>
    <visual>
      <origin
        xyz="0 0 0"
        rpy="0 0 0" />
      <geometry>
        <mesh
          filename="package://RH56DFX_R_with_Wrist/meshes/right_index_1.STL" />
      </geometry>
      <material
        name="">
        <color
          rgba="0.890196078431372 0.890196078431372 0.913725490196078 1" />
      </material>
    </visual>
    <collision>
      <origin
        xyz="0 0 0"
        rpy="0 0 0" />
      <geometry>
        <mesh
          filename="package://RH56DFX_R_with_Wrist/meshes/right_index_1.STL" />
      </geometry>
    </collision>
  </link>
  <joint
    name="right_index_1_joint"
    type="revolute">
    <origin
      xyz="0.00194532821464022 0.10413065448838 0.0481177843941552"
      rpy="3.10668606854991 0 -3.14159265358979" />
    <parent
      link="r_hand_base" />
    <child
      link="right_index_1" />
    <axis
      xyz="0 0 -1" />
    <limit
      lower="0"
      upper="1.344277"
      effort="1"
      velocity="2" />
  </joint>
  <link
    name="right_index_rubber_1">
    <inertial>
      <origin
        xyz="4.12823344703162E-07 -0.000277556590536285 -0.00810725945565738"
        rpy="0 0 0" />
      <mass
        value="0.00100751145422172" />
      <inertia
        ixx="9.52705543050406E-08"
        ixy="-6.53046825707749E-13"
        ixz="2.06723706413934E-12"
        iyy="6.33360705011126E-08"
        iyz="-1.10143899758904E-08"
        izz="8.2378638012238E-08" />
    </inertial>
    <visual>
      <origin
        xyz="0 0 0"
        rpy="0 0 0" />
      <geometry>
        <mesh
          filename="package://RH56DFX_R_with_Wrist/meshes/right_index_rubber_1.STL" />
      </geometry>
      <material
        name="">
        <color
          rgba="0.298039215686275 0.298039215686275 0.298039215686275 1" />
      </material>
    </visual>
    <collision>
      <origin
        xyz="0 0 0"
        rpy="0 0 0" />
      <geometry>
        <mesh
          filename="package://RH56DFX_R_with_Wrist/meshes/right_index_rubber_1.STL" />
      </geometry>
    </collision>
  </link>
  <joint
    name="right_index_rubber_1_joint"
    type="fixed">
    <origin
      xyz="0.0109621281837077 0.0154754543575784 0.00589908996830983"
      rpy="1.50432023539848 1.57076102968367 1.57079632679471" />
    <parent
      link="right_index_1" />
    <child
      link="right_index_rubber_1" />
    <axis
      xyz="0 0 0" />
  </joint>
  <link
    name="right_index_2">
    <inertial>
      <origin
        xyz="0.000846426534759151 0.0159697001083362 0.00510099034129251"
        rpy="0 0 0" />
      <mass
        value="0.00925229796570667" />
      <inertia
        ixx="8.02619712389298E-07"
        ixy="-2.71403950553563E-07"
        ixz="-3.30964974651346E-11"
        iyy="2.63871633501356E-07"
        iyz="-7.26892151274636E-11"
        izz="9.31350792104698E-07" />
    </inertial>
    <visual>
      <origin
        xyz="0 0 0"
        rpy="0 0 0" />
      <geometry>
        <mesh
          filename="package://RH56DFX_R_with_Wrist/meshes/right_index_2.STL" />
      </geometry>
      <material
        name="">
        <color
          rgba="0.890196078431372 0.890196078431372 0.913725490196078 1" />
      </material>
    </visual>
    <collision>
      <origin
        xyz="0 0 0"
        rpy="0 0 0" />
      <geometry>
        <mesh
          filename="package://RH56DFX_R_with_Wrist/meshes/right_index_2.STL" />
      </geometry>
    </collision>
  </link>
  <joint
    name="right_index_2_joint"
    type="revolute">
    <origin
      xyz="0.00711888977031655 0.031333910351405 0.000799999999999995"
      rpy="0 0 0" />
    <parent
      link="right_index_1" />
    <child
      link="right_index_2" />
    <axis
      xyz="0 0 -1" />
    <limit
      lower="0"
      upper="1.59562"
      effort="1"
      velocity="2" />
      <mimic 
        joint="right_index_1_joint"
        multiplier="1.1169"
        offset="-0.15" />
  </joint>
  <link
    name="right_index_rubber_2">
    <inertial>
      <origin
        xyz="-3.58356273424953E-06 0.0158538079871463 -0.000683080888343193"
        rpy="0 0 0" />
      <mass
        value="0.00119003328901229" />
      <inertia
        ixx="1.35901045730651E-07"
        ixy="-8.22113597047332E-11"
        ixz="8.26751437858824E-12"
        iyy="2.32704344501304E-08"
        iyz="-1.5965157571134E-08"
        izz="1.37434601512647E-07" />
    </inertial>
    <visual>
      <origin
        xyz="0 0 0"
        rpy="0 0 0" />
      <geometry>
        <mesh
          filename="package://RH56DFX_R_with_Wrist/meshes/right_index_rubber_2.STL" />
      </geometry>
      <material
        name="">
        <color
          rgba="0.298039215686275 0.298039215686275 0.298039215686275 1" />
      </material>
    </visual>
    <collision>
      <origin
        xyz="0 0 0"
        rpy="0 0 0" />
      <geometry>
        <mesh
          filename="package://RH56DFX_R_with_Wrist/meshes/right_index_rubber_2.STL" />
      </geometry>
    </collision>
  </link>
  <joint
    name="right_index_rubber_2_joint"
    type="fixed">
    <origin
      xyz="0.00701471041721975 0.0124857131701201 0.00505570909037727"
      rpy="1.69077174424415 1.56380581491927 1.5707963267949" />
    <parent
      link="right_index_2" />
    <child
      link="right_index_rubber_2" />
    <axis
      xyz="0 0 0" />
  </joint>
  <link
    name="right_index_pad">
    <inertial>
      <origin
        xyz="-4.72675732283989E-06 -0.00107358726165793 -0.000867322927155814"
        rpy="0 0 0" />
      <mass
        value="4.91580635340277E-05" />
      <inertia
        ixx="5.5578818727044E-11"
        ixy="-2.56095658110701E-14"
        ixz="3.01618774673413E-13"
        iyy="6.99839853074952E-11"
        iyz="-4.83794966411374E-12"
        izz="1.11177015808293E-10" />
    </inertial>
    <visual>
      <origin
        xyz="0 0 0"
        rpy="0 0 0" />
      <geometry>
        <mesh
          filename="package://RH56DFX_R_with_Wrist/meshes/right_index_pad.STL" />
      </geometry>
      <material
        name="">
        <color
          rgba="0.298039215686275 0.298039215686275 0.298039215686275 1" />
      </material>
    </visual>
    <collision>
      <origin
        xyz="0 0 0"
        rpy="0 0 0" />
      <geometry>
        <mesh
          filename="package://RH56DFX_R_with_Wrist/meshes/right_index_pad.STL" />
      </geometry>
    </collision>
  </link>
  <joint
    name="right_index_pad_joint"
    type="fixed">
    <origin
      xyz="3.00243817556722E-05 0.0237882080122733 0.00562165601406409"
      rpy="0.0696904105640824 -4.36438134320539E-05 -0.000362025901862688" />
    <parent
      link="right_index_rubber_2" />
    <child
      link="right_index_pad" />
    <axis
      xyz="0 0 0" />
  </joint>
  <link
    name="right_index_tip">
    <inertial>
      <origin
        xyz="-0.000856665440566062 1.72386023511439E-08 -0.00102183804462784"
        rpy="0 0 0" />
      <mass
        value="4.8581150755806E-05" />
      <inertia
        ixx="7.21518593802518E-11"
        ixy="-8.82984500824285E-16"
        ixz="-6.19021389144841E-12"
        iyy="4.34288558152482E-11"
        iyz="-6.09787415610097E-16"
        izz="9.51176981115546E-11" />
    </inertial>
    <visual>
      <origin
        xyz="0 0 0"
        rpy="0 0 0" />
      <geometry>
        <mesh
          filename="package://RH56DFX_R_with_Wrist/meshes/right_index_tip.STL" />
      </geometry>
      <material
        name="">
        <color
          rgba="0.298039215686275 0.298039215686275 0.298039215686275 1" />
      </material>
    </visual>
    <collision>
      <origin
        xyz="0 0 0"
        rpy="0 0 0" />
      <geometry>
        <mesh
          filename="package://RH56DFX_R_with_Wrist/meshes/right_index_tip.STL" />
      </geometry>
    </collision>
  </link>
  <joint
    name="right_index_tip_joint"
    type="fixed">
    <origin
      xyz="1.3021716642192E-05 0.0312210274719888 0.00245735122593096"
      rpy="-0.0132578490113875 -1.15442763241846 -1.55866618437752" />
    <parent
      link="right_index_rubber_2" />
    <child
      link="right_index_tip" />
    <axis
      xyz="0 0 0" />
  </joint>
  <link
    name="right_middle_1">
    <inertial>
      <origin
        xyz="0.000461536885983826 0.0116516125222235 0.00589995181961705"
        rpy="0 0 0" />
      <mass
        value="0.00881200970495173" />
      <inertia
        ixx="1.40231746759167E-06"
        ixy="-1.11031857346258E-07"
        ixz="2.76776881580569E-13"
        iyy="4.3361687442033E-07"
        iyz="-2.06120096174135E-11"
        izz="1.46953912178421E-06" />
    </inertial>
    <visual>
      <origin
        xyz="0 0 0"
        rpy="0 0 0" />
      <geometry>
        <mesh
          filename="package://RH56DFX_R_with_Wrist/meshes/right_middle_1.STL" />
      </geometry>
      <material
        name="">
        <color
          rgba="0.890196078431372 0.890196078431372 0.913725490196078 1" />
      </material>
    </visual>
    <collision>
      <origin
        xyz="0 0 0"
        rpy="0 0 0" />
      <geometry>
        <mesh
          filename="package://RH56DFX_R_with_Wrist/meshes/right_middle_1.STL" />
      </geometry>
    </collision>
  </link>
  <joint
    name="right_middle_1_joint"
    type="revolute">
    <origin
      xyz="0.00194533001909609 0.104700000000653 0.0288000018363736"
      rpy="3.14159265358979 0 -3.14159265358979" />
    <parent
      link="r_hand_base" />
    <child
      link="right_middle_1" />
    <axis
      xyz="0 0 -1" />
    <limit
      lower="0"
      upper="1.344277"
      effort="1"
      velocity="2" />
  </joint>
  <link
    name="right_middle_rubber_1">
    <inertial>
      <origin
        xyz="5.03194383060651E-07 -0.000277152008924031 -0.0081067256628847"
        rpy="0 0 0" />
      <mass
        value="0.00100745314711643" />
      <inertia
        ixx="9.52604058132886E-08"
        ixy="-6.50470587645645E-14"
        ixz="2.63599810058609E-12"
        iyy="6.33300899291808E-08"
        iyz="-1.10094889659031E-08"
        izz="8.23746488113718E-08" />
    </inertial>
    <visual>
      <origin
        xyz="0 0 0"
        rpy="0 0 0" />
      <geometry>
        <mesh
          filename="package://RH56DFX_R_with_Wrist/meshes/right_middle_rubber_1.STL" />
      </geometry>
      <material
        name="">
        <color
          rgba="0.298039215686275 0.298039215686275 0.298039215686275 1" />
      </material>
    </visual>
    <collision>
      <origin
        xyz="0 0 0"
        rpy="0 0 0" />
      <geometry>
        <mesh
          filename="package://RH56DFX_R_with_Wrist/meshes/right_middle_rubber_1.STL" />
      </geometry>
    </collision>
  </link>
  <joint
    name="right_middle_rubber_1_joint"
    type="fixed">
    <origin
      xyz="0.0109621183300843 0.015475307190653 0.00589999770412982"
      rpy="1.50432207005085 1.57079545855447 1.57079632645248" />
    <parent
      link="right_middle_1" />
    <child
      link="right_middle_rubber_1" />
    <axis
      xyz="0 0 0" />
  </joint>
  <link
    name="right_middle_2">
    <inertial>
      <origin
        xyz="0.00141024346448289 0.0172292690724932 0.00510100142947595"
        rpy="0 0 0" />
      <mass
        value="0.0100500190545245" />
      <inertia
        ixx="1.00699767773869E-06"
        ixy="-3.53466950101425E-07"
        ixz="-4.09738501779786E-11"
        iyy="3.12317850665907E-07"
        iyz="-8.9724549237976E-11"
        izz="1.17274745258556E-06" />
    </inertial>
    <visual>
      <origin
        xyz="0 0 0"
        rpy="0 0 0" />
      <geometry>
        <mesh
          filename="package://RH56DFX_R_with_Wrist/meshes/right_middle_2.STL" />
      </geometry>
      <material
        name="">
        <color
          rgba="0.890196078431372 0.890196078431372 0.913725490196078 1" />
      </material>
    </visual>
    <collision>
      <origin
        xyz="0 0 0"
        rpy="0 0 0" />
      <geometry>
        <mesh
          filename="package://RH56DFX_R_with_Wrist/meshes/right_middle_2.STL" />
      </geometry>
    </collision>
  </link>
  <joint
    name="right_middle_2_joint"
    type="revolute">
    <origin
      xyz="0.00711888977031674 0.031333910351405 0.000799999999999999"
      rpy="0 0 0" />
    <parent
      link="right_middle_1" />
    <child
      link="right_middle_2" />
    <axis
      xyz="0 0 -1" />
    <limit
      lower="0"
      upper="1.59562"
      effort="1"
      velocity="2" />
      <mimic 
        joint="right_middle_1_joint"
        multiplier="1.1169"
        offset="-0.15" />
  </joint>
  <link
    name="right_middle_rubber_2">
    <inertial>
      <origin
        xyz="-7.78660795392946E-06 0.0179695960463814 -0.000804223911115579"
        rpy="0 0 0" />
      <mass
        value="0.0013048811432833" />
      <inertia
        ixx="1.76860633231279E-07"
        ixy="-1.72710567602084E-10"
        ixz="1.86622775329528E-11"
        iyy="2.52989855308437E-08"
        iyz="-1.81372167935848E-08"
        izz="1.78751424236927E-07" />
    </inertial>
    <visual>
      <origin
        xyz="0 0 0"
        rpy="0 0 0" />
      <geometry>
        <mesh
          filename="package://RH56DFX_R_with_Wrist/meshes/right_middle_rubber_2.STL" />
      </geometry>
      <material
        name="">
        <color
          rgba="0.298039215686275 0.298039215686275 0.298039215686275 1" />
      </material>
    </visual>
    <collision>
      <origin
        xyz="0 0 0"
        rpy="0 0 0" />
      <geometry>
        <mesh
          filename="package://RH56DFX_R_with_Wrist/meshes/right_middle_rubber_2.STL" />
      </geometry>
    </collision>
  </link>
  <joint
    name="right_middle_rubber_2_joint"
    type="fixed">
    <origin
      xyz="0.00728447582119454 0.0125178675599887 0.00500175021685197"
      rpy="1.71953203312949 1.56574950814777 1.57079632679484" />
    <parent
      link="right_middle_2" />
    <child
      link="right_middle_rubber_2" />
    <axis
      xyz="0 0 0" />
  </joint>
  <link
    name="right_middle_pad">
    <inertial>
      <origin
        xyz="-9.14565195887784E-06 -0.000840646466128955 -0.000949483924762143"
        rpy="0 0 0" />
      <mass
        value="5.07972430810532E-05" />
      <inertia
        ixx="4.94396351444529E-11"
        ixy="-7.91548004686601E-15"
        ixz="5.40378231833977E-13"
        iyy="7.44594898392844E-11"
        iyz="-8.17507834331293E-13"
        izz="1.05507123106656E-10" />
    </inertial>
    <visual>
      <origin
        xyz="0 0 0"
        rpy="0 0 0" />
      <geometry>
        <mesh
          filename="package://RH56DFX_R_with_Wrist/meshes/right_middle_pad.STL" />
      </geometry>
      <material
        name="">
        <color
          rgba="0.298039215686275 0.298039215686275 0.298039215686275 1" />
      </material>
    </visual>
    <collision>
      <origin
        xyz="0 0 0"
        rpy="0 0 0" />
      <geometry>
        <mesh
          filename="package://RH56DFX_R_with_Wrist/meshes/right_middle_pad.STL" />
      </geometry>
    </collision>
  </link>
  <joint
    name="right_middle_pad_joint"
    type="fixed">
    <origin
      xyz="5.25438080711468E-05 0.0275018148385101 0.00545981715229053"
      rpy="-0.00517966246514453 0 5.23567777294042E-05" />
    <parent
      link="right_middle_rubber_2" />
    <child
      link="right_middle_pad" />
    <axis
      xyz="0 0 0" />
  </joint>
  <link
    name="right_middle_tip">
    <inertial>
      <origin
        xyz="-0.000704283128653865 1.67839236536738E-08 -0.00102507470098162"
        rpy="0 0 0" />
      <mass
        value="4.91005965538781E-05" />
      <inertia
        ixx="7.48176669074519E-11"
        ixy="-2.50173118998354E-16"
        ixz="-8.35780307730688E-12"
        iyy="4.40425756472355E-11"
        iyz="-5.51385282913369E-16"
        izz="9.36024416007487E-11" />
    </inertial>
    <visual>
      <origin
        xyz="0 0 0"
        rpy="0 0 0" />
      <geometry>
        <mesh
          filename="package://RH56DFX_R_with_Wrist/meshes/right_middle_tip.STL" />
      </geometry>
      <material
        name="">
        <color
          rgba="0.298039215686275 0.298039215686275 0.298039215686275 1" />
      </material>
    </visual>
    <collision>
      <origin
        xyz="0 0 0"
        rpy="0 0 0" />
      <geometry>
        <mesh
          filename="package://RH56DFX_R_with_Wrist/meshes/right_middle_tip.STL" />
      </geometry>
    </collision>
  </link>
  <joint
    name="right_middle_tip_joint"
    type="fixed">
    <origin
      xyz="2.14438757245201E-05 0.0347938058137771 0.00223431434988275"
      rpy="-0.0212852224193426 -1.10096720678329 -1.55181437467009" />
    <parent
      link="right_middle_rubber_2" />
    <child
      link="right_middle_tip" />
    <axis
      xyz="0 0 0" />
  </joint>
  <link
    name="right_ring_1">
    <inertial>
      <origin
        xyz="0.000461529808952352 0.0116516281013066 0.00589997080611754"
        rpy="0 0 0" />
      <mass
        value="0.00881199089266755" />
      <inertia
        ixx="1.40231626030143E-06"
        ixy="-1.11031417680239E-07"
        ixz="-4.11132338161052E-13"
        iyy="4.33615995681772E-07"
        iyz="-1.87827283777995E-11"
        izz="1.46953842944188E-06" />
    </inertial>
    <visual>
      <origin
        xyz="0 0 0"
        rpy="0 0 0" />
      <geometry>
        <mesh
          filename="package://RH56DFX_R_with_Wrist/meshes/right_ring_1.STL" />
      </geometry>
      <material
        name="">
        <color
          rgba="0.890196078431372 0.890196078431372 0.913725490196078 1" />
      </material>
    </visual>
    <collision>
      <origin
        xyz="0 0 0"
        rpy="0 0 0" />
      <geometry>
        <mesh
          filename="package://RH56DFX_R_with_Wrist/meshes/right_ring_1.STL" />
      </geometry>
    </collision>
  </link>
  <joint
    name="right_ring_1_joint"
    type="revolute">
    <origin
      xyz="0.00194533183364247 0.104505254785832 0.00956298212738258"
      rpy="-3.08923277602996 0 -3.14159265358979" />
    <parent
      link="r_hand_base" />
    <child
      link="right_ring_1" />
    <axis
      xyz="0 0 -1" />
    <limit
      lower="0"
      upper="1.344277"
      effort="1"
      velocity="2" />
  </joint>
  <link
    name="right_ring_rubber_1">
    <inertial>
      <origin
        xyz="5.2155977003465E-07 -0.00027711873325572 -0.00810658713183562"
        rpy="0 0 0" />
      <mass
        value="0.00100744692221204" />
      <inertia
        ixx="9.52590748325436E-08"
        ixy="3.14419307321927E-13"
        ixz="2.58919901200205E-12"
        iyy="6.33292870038947E-08"
        iyz="-1.10085765951351E-08"
        izz="8.23741747990365E-08" />
    </inertial>
    <visual>
      <origin
        xyz="0 0 0"
        rpy="0 0 0" />
      <geometry>
        <mesh
          filename="package://RH56DFX_R_with_Wrist/meshes/right_ring_rubber_1.STL" />
      </geometry>
      <material
        name="">
        <color
          rgba="0.298039215686275 0.298039215686275 0.298039215686275 1" />
      </material>
    </visual>
    <collision>
      <origin
        xyz="0 0 0"
        rpy="0 0 0" />
      <geometry>
        <mesh
          filename="package://RH56DFX_R_with_Wrist/meshes/right_ring_rubber_1.STL" />
      </geometry>
    </collision>
  </link>
  <joint
    name="right_ring_rubber_1_joint"
    type="fixed">
    <origin
      xyz="0.010962118330056 0.0154753071906455 0.00589999770412788"
      rpy="1.50432207039055 1.57079545829877 1.57079632679123" />
    <parent
      link="right_ring_1" />
    <child
      link="right_ring_rubber_1" />
    <axis
      xyz="0 0 0" />
  </joint>
  <link
    name="right_ring_2">
    <inertial>
      <origin
        xyz="0.000846433960369861 0.0159697337276641 0.00510097835693506"
        rpy="0 0 0" />
      <mass
        value="0.00925228640460225" />
      <inertia
        ixx="8.02618879630186E-07"
        ixy="-2.71404191071111E-07"
        ixz="-3.36930516319959E-11"
        iyy="2.63871764022255E-07"
        iyz="-7.22696351068233E-11"
        izz="9.3134922642369E-07" />
    </inertial>
    <visual>
      <origin
        xyz="0 0 0"
        rpy="0 0 0" />
      <geometry>
        <mesh
          filename="package://RH56DFX_R_with_Wrist/meshes/right_ring_2.STL" />
      </geometry>
      <material
        name="">
        <color
          rgba="0.890196078431372 0.890196078431372 0.913725490196078 1" />
      </material>
    </visual>
    <collision>
      <origin
        xyz="0 0 0"
        rpy="0 0 0" />
      <geometry>
        <mesh
          filename="package://RH56DFX_R_with_Wrist/meshes/right_ring_2.STL" />
      </geometry>
    </collision>
  </link>
  <joint
    name="right_ring_2_joint"
    type="revolute">
    <origin
      xyz="0.00711888977031674 0.031333910351405 0.000800000000000002"
      rpy="0 0 0" />
    <parent
      link="right_ring_1" />
    <child
      link="right_ring_2" />
    <axis
      xyz="0 0 -1" />
    <limit
      lower="0"
      upper="1.59562"
      effort="1"
      velocity="2" />
      <mimic 
        joint="right_ring_1_joint"
        multiplier="1.1169"
        offset="-0.15" />
  </joint>
  <link
    name="right_ring_rubber_2">
    <inertial>
      <origin
        xyz="3.86139388208707E-06 0.0158537656121268 -0.000683069774846418"
        rpy="0 0 0" />
      <mass
        value="0.00119005024637797" />
      <inertia
        ixx="1.3590239064115E-07"
        ixy="9.33554288461451E-11"
        ixz="-8.65081377481606E-12"
        iyy="2.32706293689469E-08"
        iyz="-1.59652938631654E-08"
        izz="1.37436006921243E-07" />
    </inertial>
    <visual>
      <origin
        xyz="0 0 0"
        rpy="0 0 0" />
      <geometry>
        <mesh
          filename="package://RH56DFX_R_with_Wrist/meshes/right_ring_rubber_2.STL" />
      </geometry>
      <material
        name="">
        <color
          rgba="0.298039215686275 0.298039215686275 0.298039215686275 1" />
      </material>
    </visual>
    <collision>
      <origin
        xyz="0 0 0"
        rpy="0 0 0" />
      <geometry>
        <mesh
          filename="package://RH56DFX_R_with_Wrist/meshes/right_ring_rubber_2.STL" />
      </geometry>
    </collision>
  </link>
  <joint
    name="right_ring_rubber_2_joint"
    type="fixed">
    <origin
      xyz="0.00685339412965266 0.0123693480371164 0.0050852021440689"
      rpy="1.69435491572921 1.55693797492977 1.5707963267949" />
    <parent
      link="right_ring_2" />
    <child
      link="right_ring_rubber_2" />
    <axis
      xyz="0 0 0" />
  </joint>
  <link
    name="right_ring_pad">
    <inertial>
      <origin
        xyz="4.93671885636732E-06 -0.00107358739426554 -0.000867321750761263"
        rpy="0 0 0" />
      <mass
        value="4.91580616058684E-05" />
      <inertia
        ixx="5.55789971203641E-11"
        ixy="2.8294541287042E-14"
        ixz="-3.17865063864846E-13"
        iyy="6.99839909074725E-11"
        iyz="-4.83793120453108E-12"
        izz="1.11176836090907E-10" />
    </inertial>
    <visual>
      <origin
        xyz="0 0 0"
        rpy="0 0 0" />
      <geometry>
        <mesh
          filename="package://RH56DFX_R_with_Wrist/meshes/right_ring_pad.STL" />
      </geometry>
      <material
        name="">
        <color
          rgba="0.298039215686275 0.298039215686275 0.298039215686275 1" />
      </material>
    </visual>
    <collision>
      <origin
        xyz="0 0 0"
        rpy="0 0 0" />
      <geometry>
        <mesh
          filename="package://RH56DFX_R_with_Wrist/meshes/right_ring_pad.STL" />
      </geometry>
    </collision>
  </link>
  <joint
    name="right_ring_pad_joint"
    type="fixed">
    <origin
      xyz="-3.19252405448149E-05 0.023788208012268 0.0056216455404758"
      rpy="0.069690128142456 5.13938714334209E-05 0.000413828517329857" />
    <parent
      link="right_ring_rubber_2" />
    <child
      link="right_ring_pad" />
    <axis
      xyz="0 0 0" />
  </joint>
  <link
    name="right_ring_tip">
    <inertial>
      <origin
        xyz="-0.000856664915059729 1.84558855676441E-08 -0.00102183703604268"
        rpy="0 0 0" />
      <mass
        value="4.85811800950388E-05" />
      <inertia
        ixx="7.21518845124189E-11"
        ixy="-9.0667400067332E-16"
        ixz="-6.19024133610583E-12"
        iyy="4.3428909706311E-11"
        iyz="-6.22904562535281E-16"
        izz="9.5117698350311E-11" />
    </inertial>
    <visual>
      <origin
        xyz="0 0 0"
        rpy="0 0 0" />
      <geometry>
        <mesh
          filename="package://RH56DFX_R_with_Wrist/meshes/right_ring_tip.STL" />
      </geometry>
      <material
        name="">
        <color
          rgba="0.298039215686275 0.298039215686275 0.298039215686275 1" />
      </material>
    </visual>
    <collision>
      <origin
        xyz="0 0 0"
        rpy="0 0 0" />
      <geometry>
        <mesh
          filename="package://RH56DFX_R_with_Wrist/meshes/right_ring_tip.STL" />
      </geometry>
    </collision>
  </link>
  <joint
    name="right_ring_tip_joint"
    type="fixed">
    <origin
      xyz="-1.40578386722194E-05 0.031221027471983 0.00245734551696726"
      rpy="0.0139894535346192 -1.15442399923571 -1.58358580818303" />
    <parent
      link="right_ring_rubber_2" />
    <child
      link="right_ring_tip" />
    <axis
      xyz="0 0 0" />
  </joint>
  <link
    name="right_little_1">
    <inertial>
      <origin
        xyz="0.000461535865010715 0.0116516313664566 0.00589997438900396"
        rpy="0 0 0" />
      <mass
        value="0.00881199742105912" />
      <inertia
        ixx="1.40231644763056E-06"
        ixy="-1.11031114077316E-07"
        ixz="-6.64626601708415E-13"
        iyy="4.33616376568148E-07"
        iyz="-1.83961470302043E-11"
        izz="1.46953909499787E-06" />
    </inertial>
    <visual>
      <origin
        xyz="0 0 0"
        rpy="0 0 0" />
      <geometry>
        <mesh
          filename="package://RH56DFX_R_with_Wrist/meshes/right_little_1.STL" />
      </geometry>
      <material
        name="">
        <color
          rgba="0.890196078431372 0.890196078431372 0.913725490196078 1" />
      </material>
    </visual>
    <collision>
      <origin
        xyz="0 0 0"
        rpy="0 0 0" />
      <geometry>
        <mesh
          filename="package://RH56DFX_R_with_Wrist/meshes/right_little_1.STL" />
      </geometry>
    </collision>
  </link>
  <joint
    name="right_little_1_joint"
    type="revolute">
    <origin
      xyz="0.00194533363591419 0.103303988640658 -0.00963748173991816"
      rpy="-3.03687289847015 0 -3.14159265358979" />
    <parent
      link="r_hand_base" />
    <child
      link="right_little_1" />
    <axis
      xyz="0 0 -1" />
    <limit
      lower="0"
      upper="1.344277"
      effort="1"
      velocity="2" />
  </joint>
  <link
    name="right_little_rubber_1">
    <inertial>
      <origin
        xyz="5.2001515208136E-07 -0.000277124167245069 -0.00810660264781775"
        rpy="0 0 0" />
      <mass
        value="0.00100745344385294" />
      <inertia
        ixx="9.52596117756999E-08"
        ixy="2.53394691235758E-13"
        ixz="2.57916023682324E-12"
        iyy="6.33296358817012E-08"
        iyz="-1.10088359707623E-08"
        izz="8.23744527124975E-08" />
    </inertial>
    <visual>
      <origin
        xyz="0 0 0"
        rpy="0 0 0" />
      <geometry>
        <mesh
          filename="package://RH56DFX_R_with_Wrist/meshes/right_little_rubber_1.STL" />
      </geometry>
      <material
        name="">
        <color
          rgba="0.298039215686275 0.298039215686275 0.298039215686275 1" />
      </material>
    </visual>
    <collision>
      <origin
        xyz="0 0 0"
        rpy="0 0 0" />
      <geometry>
        <mesh
          filename="package://RH56DFX_R_with_Wrist/meshes/right_little_rubber_1.STL" />
      </geometry>
    </collision>
  </link>
  <joint
    name="right_little_rubber_1_joint"
    type="fixed">
    <origin
      xyz="0.0109621183300826 0.0154753071906525 0.00589999770412923"
      rpy="1.50432207044638 1.57079545804314 1.57079632684632" />
    <parent
      link="right_little_1" />
    <child
      link="right_little_rubber_1" />
    <axis
      xyz="0 0 0" />
  </joint>
  <link
    name="right_little_2">
    <inertial>
      <origin
        xyz="-9.65934753168612E-05 0.0131706385669229 0.00510089546104599"
        rpy="0 0 0" />
      <mass
        value="0.00735975645438557" />
      <inertia
        ixx="4.52987650882817E-07"
        ixy="-1.39947116144588E-07"
        ixz="-1.99302269281013E-11"
        iyy="1.74903368778748E-07"
        iyz="-4.32909879788334E-11"
        izz="5.20977818958806E-07" />
    </inertial>
    <visual>
      <origin
        xyz="0 0 0"
        rpy="0 0 0" />
      <geometry>
        <mesh
          filename="package://RH56DFX_R_with_Wrist/meshes/right_little_2.STL" />
      </geometry>
      <material
        name="">
        <color
          rgba="0.890196078431372 0.890196078431372 0.913725490196078 1" />
      </material>
    </visual>
    <collision>
      <origin
        xyz="0 0 0"
        rpy="0 0 0" />
      <geometry>
        <mesh
          filename="package://RH56DFX_R_with_Wrist/meshes/right_little_2.STL" />
      </geometry>
    </collision>
  </link>
  <joint
    name="right_little_2_joint"
    type="revolute">
    <origin
      xyz="0.00711888977031679 0.0313339103514049 0.0008"
      rpy="0 0 0" />
    <parent
      link="right_little_1" />
    <child
      link="right_little_2" />
    <axis
      xyz="0 0 -1" />
    <limit
      lower="0"
      upper="1.59562"
      effort="1"
      velocity="2" />
      <mimic 
        joint="right_little_1_joint"
        multiplier="1.1169"
        offset="-0.15" />
  </joint>
  <link
    name="right_little_rubber_2">
    <inertial>
      <origin
        xyz="1.62425876137906E-07 0.0112748945844156 -0.000128890409676133"
        rpy="0 0 0" />
      <mass
        value="0.000944695125035103" />
      <inertia
        ixx="7.2727499654919E-08"
        ixy="5.77567509575788E-13"
        ixz="3.35299338500849E-13"
        iyy="1.97518492029983E-08"
        iyz="-1.31116172495388E-08"
        izz="7.2809424232253E-08" />
    </inertial>
    <visual>
      <origin
        xyz="0 0 0"
        rpy="0 0 0" />
      <geometry>
        <mesh
          filename="package://RH56DFX_R_with_Wrist/meshes/right_little_rubber_2.STL" />
      </geometry>
      <material
        name="">
        <color
          rgba="0.298039215686275 0.298039215686275 0.298039215686275 1" />
      </material>
    </visual>
    <collision>
      <origin
        xyz="0 0 0"
        rpy="0 0 0" />
      <geometry>
        <mesh
          filename="package://RH56DFX_R_with_Wrist/meshes/right_little_rubber_2.STL" />
      </geometry>
    </collision>
  </link>
  <joint
    name="right_little_rubber_2_joint"
    type="fixed">
    <origin
      xyz="0.00605975881840991 0.0120279982928333 0.00510001089644302"
      rpy="-1.56390542593735 1.5707956711438 -1.57079632686305" />
    <parent
      link="right_little_2" />
    <child
      link="right_little_rubber_2" />
    <axis
      xyz="0 0 0" />
  </joint>
  <link
    name="right_little_pad">
    <inertial>
      <origin
        xyz="1.18945155044847E-08 -0.000945393602624772 -0.000793542159615288"
        rpy="0 0 0" />
      <mass
        value="4.11773981011346E-05" />
      <inertia
        ixx="3.93905948672135E-11"
        ixy="-7.32805647857825E-16"
        ixz="1.26379267654582E-16"
        iyy="5.76290636184782E-11"
        iyz="-3.06558460120779E-12"
        izz="8.71440947947964E-11" />
    </inertial>
    <visual>
      <origin
        xyz="0 0 0"
        rpy="0 0 0" />
      <geometry>
        <mesh
          filename="package://RH56DFX_R_with_Wrist/meshes/right_little_pad.STL" />
      </geometry>
      <material
        name="">
        <color
          rgba="0.298039215686275 0.298039215686275 0.298039215686275 1" />
      </material>
    </visual>
    <collision>
      <origin
        xyz="0 0 0"
        rpy="0 0 0" />
      <geometry>
        <mesh
          filename="package://RH56DFX_R_with_Wrist/meshes/right_little_pad.STL" />
      </geometry>
    </collision>
  </link>
  <joint
    name="right_little_pad_joint"
    type="fixed">
    <origin
      xyz="0 0.0158106591438756 0.00622450938719539"
      rpy="0.234319161981939 0 0" />
    <parent
      link="right_little_rubber_2" />
    <child
      link="right_little_pad" />
    <axis
      xyz="0 0 0" />
  </joint>
  <link
    name="right_little_tip">
    <inertial>
      <origin
        xyz="-0.000679510924646992 -6.02486744175068E-09 -0.000989969384403752"
        rpy="0 0 0" />
      <mass
        value="5.12498578797036E-05" />
      <inertia
        ixx="7.82782292969908E-11"
        ixy="-1.77725923700193E-16"
        ixz="-6.68409720589241E-12"
        iyy="4.68632553260876E-11"
        iyz="4.1284142734597E-17"
        izz="1.00471412022202E-10" />
    </inertial>
    <visual>
      <origin
        xyz="0 0 0"
        rpy="0 0 0" />
      <geometry>
        <mesh
          filename="package://RH56DFX_R_with_Wrist/meshes/right_little_tip.STL" />
      </geometry>
      <material
        name="">
        <color
          rgba="0.298039215686275 0.298039215686275 0.298039215686275 1" />
      </material>
    </visual>
    <collision>
      <origin
        xyz="0 0 0"
        rpy="0 0 0" />
      <geometry>
        <mesh
          filename="package://RH56DFX_R_with_Wrist/meshes/right_little_tip.STL" />
      </geometry>
    </collision>
  </link>
  <joint
    name="right_little_tip_joint"
    type="fixed">
    <origin
      xyz="0 0.0235281291193636 0.00364793083244132"
      rpy="0 -1.19148502417136 -1.57079698453249" />
    <parent
      link="right_little_rubber_2" />
    <child
      link="right_little_tip" />
    <axis
      xyz="0 0 0" />
  </joint>
  <link
    name="plam">
    <inertial>
      <origin
        xyz="-0.00487476115199903 -0.00792590594901733 0.000407287403266149"
        rpy="0 0 0" />
      <mass
        value="0.0103872606304316" />
      <inertia
        ixx="4.3257392285981E-06"
        ixy="-1.82977028635989E-06"
        ixz="1.24432802905896E-07"
        iyy="5.02164658576807E-06"
        iyz="6.08810899487125E-07"
        izz="9.01614152174615E-06" />
    </inertial>
    <visual>
      <origin
        xyz="0 0 0"
        rpy="0 0 0" />
      <geometry>
        <mesh
          filename="package://RH56DFX_R_with_Wrist/meshes/plam.STL" />
      </geometry>
      <material
        name="">
        <color
          rgba="0.298039215686275 0.298039215686275 0.298039215686275 1" />
      </material>
    </visual>
    <collision>
      <origin
        xyz="0 0 0"
        rpy="0 0 0" />
      <geometry>
        <mesh
          filename="package://RH56DFX_R_with_Wrist/meshes/plam.STL" />
      </geometry>
    </collision>
  </link>
  <joint
    name="plam_joint"
    type="fixed">
    <origin
      xyz="-0.0127026875381151 0.0690813613769987 0.0114985605408958"
      rpy="-3.14159265245797 -1.57079623022433 3.14159265245797" />
    <parent
      link="r_hand_base" />
    <child
      link="plam" />
    <axis
      xyz="0 0 0" />
  </joint>
</robot>
