<mujoco model="RH56DFX_R">
  <compiler angle="radian"/>

  <asset>
    <mesh name="r_hand_base" file="r_hand_base.STL"/>
    <mesh name="right_thumb_1" file="right_thumb_1.STL"/>
    <mesh name="right_thumb_2" file="right_thumb_2.STL"/>
    <mesh name="right_thumb_3" file="right_thumb_3.STL"/>
    <mesh name="right_thumb_4" file="right_thumb_4.STL"/>
    <mesh name="right_thumb_rubber_3" file="right_thumb_rubber_3.STL"/>
    <mesh name="right_thumb_pad" file="right_thumb_pad.STL"/>
    <mesh name="right_thumb_tip" file="right_thumb_tip.STL"/>
    <mesh name="right_thumb_rubber_2" file="right_thumb_rubber_2.STL"/>
    <mesh name="right_thumb_rubber_1" file="right_thumb_rubber_1.STL"/>
    <mesh name="right_index_1" file="right_index_1.STL"/>
    <mesh name="right_index_rubber_1" file="right_index_rubber_1.STL"/>
    <mesh name="right_index_2" file="right_index_2.STL"/>
    <mesh name="right_index_rubber_2" file="right_index_rubber_2.STL"/>
    <mesh name="right_index_pad" file="right_index_pad.STL"/>
    <mesh name="right_index_tip" file="right_index_tip.STL"/>
    <mesh name="right_middle_1" file="right_middle_1.STL"/>
    <mesh name="right_middle_rubber_1" file="right_middle_rubber_1.STL"/>
    <mesh name="right_middle_2" file="right_middle_2.STL"/>
    <mesh name="right_middle_rubber_2" file="right_middle_rubber_2.STL"/>
    <mesh name="right_middle_pad" file="right_middle_pad.STL"/>
    <mesh name="right_middle_tip" file="right_middle_tip.STL"/>
    <mesh name="right_ring_1" file="right_ring_1.STL"/>
    <mesh name="right_ring_rubber_1" file="right_ring_rubber_1.STL"/>
    <mesh name="right_ring_2" file="right_ring_2.STL"/>
    <mesh name="right_ring_rubber_2" file="right_ring_rubber_2.STL"/>
    <mesh name="right_ring_pad" file="right_ring_pad.STL"/>
    <mesh name="right_ring_tip" file="right_ring_tip.STL"/>
    <mesh name="right_little_1" file="right_little_1.STL"/>
    <mesh name="right_little_rubber_1" file="right_little_rubber_1.STL"/>
    <mesh name="right_little_2" file="right_little_2.STL"/>
    <mesh name="right_little_rubber_2" file="right_little_rubber_2.STL"/>
    <mesh name="right_little_pad" file="right_little_pad.STL"/>
    <mesh name="right_little_tip" file="right_little_tip.STL"/>
    <mesh name="plam" file="plam.STL"/>
  </asset>

  <worldbody>
    <geom pos="-0.00186722142687372 -0.03425462641545 -0.014403857640475" type="mesh" rgba="1 1 1 1" mesh="r_hand_base"/>
    <geom pos="-0.01456992142687372 0.03482677358455 -0.002905257640475" quat="0.707107 0 -0.707107 0" type="mesh" rgba="0.298039 0.298039 0.298039 1" mesh="plam"/>
    <body name="right_thumb_1" pos="-0.01716722142687372 0.00004537358455 0.021996142359525" quat="0 0 -0.707107 -0.707107">
      <inertial pos="0.000675361 0.00433554 -0.0050878" quat="0.619086 0.751082 -0.181482 -0.140258" mass="0.00485415" diaginertia="2.13426e-07 1.7068e-07 1.24203e-07"/>
      <joint name="right_thumb_1_joint" pos="0 0 0" axis="0 0 -1" range="0 1.31038" actuatorfrcrange="-1 1"/>
      <geom type="mesh" rgba="0.827451 0.839216 0.827451 1" mesh="right_thumb_1"/>
      <body name="right_thumb_2" pos="0.0107038 0.00903759 -0.0065" quat="0.430459 0.430459 -0.560986 -0.560986">
        <inertial pos="-0.0213518 0.0145309 0.00802283" quat="0.255014 0.659333 -0.255353 0.659577" mass="0.0329547" diaginertia="9.87866e-06 7.50076e-06 3.11031e-06"/>
        <joint name="right_thumb_2_joint" pos="0 0 0" axis="0 0 -1" range="0 0.523477" actuatorfrcrange="-1 1"/>
        <geom type="mesh" rgba="0.890196 0.890196 0.913725 1" mesh="right_thumb_2"/>
        <geom pos="-0.0130466 0.0313856 0.00799913" quat="0.626091 -0.324021 0.632616 0.320651" type="mesh" rgba="0.298039 0.298039 0.298039 1" mesh="right_thumb_rubber_1"/>
        <body name="right_thumb_3" pos="-0.0415839 0.0375081 0.0005">
          <inertial pos="-0.00945832 0.000357519 0.00750055" quat="0.336034 0.622164 -0.336042 0.622149" mass="0.00708967" diaginertia="9.1027e-07 8.85425e-07 4.94039e-07"/>
          <joint name="right_thumb_3_joint" pos="0 0 0" axis="0 0 -1" range="0 0.606844" actuatorfrcrange="-1 1"/>
          <geom type="mesh" rgba="0.890196 0.890196 0.913725 1" mesh="right_thumb_3"/>
          <geom pos="-0.00507003 0.0118736 0.00749999" quat="0.606877 -0.35677 0.617697 0.350521" type="mesh" rgba="0.298039 0.298039 0.298039 1" mesh="right_thumb_rubber_2"/>
          <body name="right_thumb_4" pos="-0.0183934 0.0132219 0.0015">
            <inertial pos="-0.00758789 0.00593154 0.00599414" quat="0.30807 0.6349 -0.312695 0.63578" mass="0.0051348" diaginertia="3.30345e-07 3.17199e-07 1.06531e-07"/>
            <joint name="right_thumb_4_joint" pos="0 0 0" axis="0 0 -1" range="0 0.430866" actuatorfrcrange="-1 1"/>
            <geom type="mesh" rgba="0.890196 0.890196 0.913725 1" mesh="right_thumb_4"/>
            <geom pos="-0.001618 0.00970901 0.006" quat="0.670231 -0.207968 0.68252 0.204222" type="mesh" rgba="0.298039 0.298039 0.298039 1" mesh="right_thumb_rubber_3"/>
            <geom pos="-0.0069134 0.0156409 0.00600001" quat="0.634446 -0.312208 0.634449 0.312216" type="mesh" rgba="0.298039 0.298039 0.298039 1" mesh="right_thumb_pad"/>
            <geom pos="-0.0162647 0.0179854 0.00599992" quat="0.403047 -0.578812 0.397603 0.586892" type="mesh" rgba="0.298039 0.298039 0.298039 1" mesh="right_thumb_tip"/>
            <site name="right_thumb_tip_sphere" pos="-0.0162647 0.0179854 0.00599992" type="sphere" size="0.001" rgba="1 0 0 1"/>
          </body>
        </body>
      </body>
    </body>
    <body name="right_index_1" pos="0.00007810857312628 0.06987637358455 0.033713942359525" quat="0 0 -0.999848 -0.0174524">
      <inertial pos="0.000710797 0.0119599 0.00589991" quat="0.530357 0.467677 -0.530359 0.467675" mass="0.00981978" diaginertia="1.57838e-06 1.51036e-06 4.84869e-07"/>
      <joint name="right_index_1_joint" pos="0 0 0" axis="0 0 -1" range="0 1.34428" actuatorfrcrange="-1 1"/>
      <geom type="mesh" rgba="0.890196 0.890196 0.913725 1" mesh="right_index_1"/>
      <geom pos="0.0109621 0.0154755 0.00589909" quat="0.706717 -0.023486 0.706716 0.023511" type="mesh" rgba="0.298039 0.298039 0.298039 1" mesh="right_index_rubber_1"/>
      <body name="right_index_2" pos="0.00711889 0.0313339 0.0008">
        <inertial pos="0.00179479 0.0175727 0.0051099" quat="0.590508 0.386574 -0.592837 0.38782" mass="0.0105401" diaginertia="1.34364e-06 1.32399e-06 1.79858e-07"/>
        <joint name="right_index_2_joint" pos="0 0 0" axis="0 0 -1" range="0 1.59562" actuatorfrcrange="-1 1"/>
        <geom type="mesh" rgba="0.890196 0.890196 0.913725 1" mesh="right_index_2"/>
        <geom pos="0.00701471 0.0124857 0.00505571" quat="0.705682 0.0448591 0.705979 -0.039925" type="mesh" rgba="0.298039 0.298039 0.298039 1" mesh="right_index_rubber_2"/>
        <geom pos="0.0154431 0.0354297 0.00518608" quat="0.703704 0.0692882 0.704148 -0.0646241" type="mesh" rgba="0.298039 0.298039 0.298039 1" mesh="right_index_pad"/>
        <geom pos="0.0131912 0.0431875 0.00525731" quat="0.683935 -0.679725 0.189872 -0.184812" type="mesh" rgba="0.298039 0.298039 0.298039 1" mesh="right_index_tip"/>
        <site name="right_index_tip_sphere" pos="0.0131912 0.0431875 0.00525731" type="sphere" size="0.001" rgba="1 0 0 1"/>
      </body>
    </body>
    <body name="right_middle_1" pos="0.00007810857312628 0.07044537358455 0.014396142359525" quat="0 0 -1 0">
      <inertial pos="0.000710866 0.0119603 0.0058999" quat="0.530357 0.467684 -0.530359 0.467668" mass="0.00981946" diaginertia="1.57832e-06 1.5103e-06 4.84858e-07"/>
      <joint name="right_middle_1_joint" pos="0 0 0" axis="0 0 -1" range="0 1.34428" actuatorfrcrange="-1 1"/>
      <geom type="mesh" rgba="0.890196 0.890196 0.913725 1" mesh="right_middle_1"/>
      <geom pos="0.0109621 0.0154753 0.0059" quat="0.706716 -0.0234976 0.706716 0.0234982" type="mesh" rgba="0.298039 0.298039 0.298039 1" mesh="right_middle_rubber_1"/>
      <body name="right_middle_2" pos="0.00711889 0.0313339 0.0008">
        <inertial pos="0.00240726 0.0189476 0.00510107" quat="0.591748 0.38821 -0.591216 0.38677" mass="0.0114548" diaginertia="1.69034e-06 1.66844e-06 1.95919e-07"/>
        <joint name="right_middle_2_joint" pos="0 0 0" axis="0 0 -1" range="0 1.59562" actuatorfrcrange="-1 1"/>
        <geom type="mesh" rgba="0.890196 0.890196 0.913725 1" mesh="right_middle_2"/>
        <geom pos="0.00728448 0.0125179 0.00500175" quat="0.705018 0.0543168 0.705283 -0.050758" type="mesh" rgba="0.298039 0.298039 0.298039 1" mesh="right_middle_rubber_2"/>
        <geom pos="0.0167594 0.0389069 0.00508239" quat="0.705157 0.0525092 0.70541 -0.0489128" type="mesh" rgba="0.298039 0.298039 0.298039 1" mesh="right_middle_pad"/>
        <geom pos="0.0146501 0.0465961 0.00515229" quat="0.674713 -0.672401 0.219089 -0.211277" type="mesh" rgba="0.298039 0.298039 0.298039 1" mesh="right_middle_tip"/>
        <site name="right_middle_tip_sphere" pos="0.0146501 0.0465961 0.00515229" type="sphere" size="0.001" rgba="1 0 0 1"/>
      </body>
    </body>
    <body name="right_ring_1" pos="0.00007810857312628 0.07025037358455 -0.004840877640475" quat="0 0 0.999657 -0.0261769">
      <inertial pos="0.000710873 0.0119603 0.00589992" quat="0.530353 0.46768 -0.530362 0.467672" mass="0.00981944" diaginertia="1.57832e-06 1.5103e-06 4.84858e-07"/>
      <joint name="right_ring_1_joint" pos="0 0 0" axis="0 0 -1" range="0 1.34428" actuatorfrcrange="-1 1"/>
      <geom type="mesh" rgba="0.890196 0.890196 0.913725 1" mesh="right_ring_1"/>
      <geom pos="0.0109621 0.0154753 0.0059" quat="0.706716 -0.0234976 0.706716 0.0234982" type="mesh" rgba="0.298039 0.298039 0.298039 1" mesh="right_ring_rubber_1"/>
      <body name="right_ring_2" pos="0.00711889 0.0313339 0.0008">
        <inertial pos="0.00178237 0.0175576 0.00512688" quat="0.588365 0.385501 -0.594765 0.389192" mass="0.0105401" diaginertia="1.33822e-06 1.31893e-06 1.79586e-07"/>
        <joint name="right_ring_2_joint" pos="0 0 0" axis="0 0 -1" range="0 1.59562" actuatorfrcrange="-1 1"/>
        <geom type="mesh" rgba="0.890196 0.890196 0.913725 1" mesh="right_ring_2"/>
        <geom pos="0.00685339 0.0123693 0.0050852" quat="0.705438 0.048546 0.706043 -0.0387654" type="mesh" rgba="0.298039 0.298039 0.298039 1" mesh="right_ring_rubber_2"/>
        <geom pos="0.0153639 0.0352807 0.00543466" quat="0.703304 0.0732392 0.704277 -0.0631922" type="mesh" rgba="0.298039 0.298039 0.298039 1" mesh="right_ring_pad"/>
        <geom pos="0.0131398 0.0430464 0.00552442" quat="0.686493 -0.676462 0.187908 -0.189252" type="mesh" rgba="0.298039 0.298039 0.298039 1" mesh="right_ring_tip"/>
        <site name="right_ring_tip_sphere" pos="0.0131398 0.0430464 0.00552442" type="sphere" size="0.001" rgba="1 0 0 1"/>
      </body>
    </body>
    <body name="right_little_1" pos="0.00007810857312628 0.06904937358455 -0.024041337640475" quat="0 0 0.99863 -0.052336">
      <inertial pos="0.000710878 0.0119603 0.00589992" quat="0.530353 0.46768 -0.530362 0.467672" mass="0.00981945" diaginertia="1.57832e-06 1.5103e-06 4.84858e-07"/>
      <joint name="right_little_1_joint" pos="0 0 0" axis="0 0 -1" range="0 1.34428" actuatorfrcrange="-1 1"/>
      <geom type="mesh" rgba="0.890196 0.890196 0.913725 1" mesh="right_little_1"/>
      <geom pos="0.0109621 0.0154753 0.0059" quat="0.706716 -0.0234976 0.706716 0.0234982" type="mesh" rgba="0.298039 0.298039 0.298039 1" mesh="right_little_rubber_1"/>
      <body name="right_little_2" pos="0.00711889 0.0313339 0.0008">
        <inertial pos="0.000701343 0.0145112 0.00510077" quat="0.59179 0.387005 -0.591825 0.386982" mass="0.00839688" diaginertia="7.47202e-07 7.35801e-07 1.38386e-07"/>
        <joint name="right_little_2_joint" pos="0 0 0" axis="0 0 -1" range="0 1.59562" actuatorfrcrange="-1 1"/>
        <geom type="mesh" rgba="0.890196 0.890196 0.913725 1" mesh="right_little_2"/>
        <geom pos="0.00605976 0.012028 0.00510001" quat="0.707103 0.00243606 0.707103 -0.00243653" type="mesh" rgba="0.298039 0.298039 0.298039 1" mesh="right_little_rubber_2"/>
        <geom pos="0.0123931 0.0277954 0.0051" quat="0.70197 0.0850738 0.70197 -0.0850743" type="mesh" rgba="0.298039 0.298039 0.298039 1" mesh="right_little_pad"/>
        <geom pos="0.00986973 0.0355304 0.0051" quat="0.693964 -0.693965 0.135696 -0.135696" type="mesh" rgba="0.298039 0.298039 0.298039 1" mesh="right_little_tip"/>
        <site name="right_pinky_tip_sphere" pos="0.00986973 0.0355304 0.0051" type="sphere" size="0.001" rgba="1 0 0 1"/>
      </body>
    </body>
    <site name="thumb_tip_target" pos="-0.05 0.08 0.05" type="sphere" size="0.005" rgba="0 1 0 1"/>
    <site name="index_tip_target" pos="-0.05 0.08 0.05" type="sphere" size="0.005" rgba="0 1 0 1"/>
    <site name="middle_tip_target" pos="-0.05 0.08 0.05" type="sphere" size="0.005" rgba="0 1 0 1"/>
    <site name="ring_tip_target" pos="-0.05 0.08 0.05" type="sphere" size="0.005" rgba="0 1 0 1"/>
    <site name="pinky_tip_target" pos="-0.05 0.08 0.05" type="sphere" size="0.005" rgba="0 1 0 1"/>
  </worldbody>
</mujoco>
